<?xml version="1.0" encoding="UTF-8"?>
<sdf version='1.9'>
  <model name='barge'>
    <pose>0 0 0 0 0 0</pose> <!-- 1 0 -1 -->

    <!-- LINKS -->
    <link name='root'>
      <pose>0 0 0 0 0 0</pose>
    </link>
    
    <link name='base'>
      <pose relative_to='root'>0 0 0 0 0 0</pose>

      <visual name='base_visual'>
        <geometry>
          <box>
            <size>0.5 0.5 0.05</size>
          </box>
        </geometry>
        <material>
          <diffuse>1 1 1 1</diffuse>
          <specular>0.4 0.4 0.4 1</specular>
          <pbr>
            <metal>
              <albedo_map>model://arucotag/arucotag.png</albedo_map>
            </metal>
          </pbr>
        </material>
      </visual>

      <collision name='base_collision'>
        <geometry>
          <box>
            <size>0.5 0.5 0.05</size>
          </box>
        </geometry>
        <surface>
          <friction>
            <ode>
              <mu>1.0</mu>
              <mu2>1.0</mu2>
            </ode>
          </friction>
          <bounce>
            <restitution_coefficient>0.1</restitution_coefficient>
            <threshold>1.0</threshold>
          </bounce>
        </surface>
      </collision>
    </link>

    <link name='lower_platform'>
      <pose>0 0 -0.01 0 0 0</pose>
      <visual name='lower_platform_visual'>
        <geometry>
          <box>
            <size>2 2 0.04</size>
          </box>
        </geometry>
        <material>
          <diffuse>0.6 0.8 0.6 1</diffuse>
          <specular>0.4 0.4 0.4 1</specular>
        </material>
      </visual>
      <collision name='lower_platform_collision'>
        <geometry>
          <box>
            <size>2 2 0.04</size>
          </box>
        </geometry>
        <surface>
          <friction>
            <ode>
              <mu>1.0</mu>
              <mu2>1.0</mu2>
            </ode>
          </friction>
          <bounce>
            <restitution_coefficient>0.1</restitution_coefficient>
            <threshold>1.0</threshold>
          </bounce>
        </surface>
      </collision>
    </link>

    <!-- JOINTS -->
    <joint name="heave" type="prismatic">
      <parent>root</parent>
      <child>base</child>
        <pose>0 0 0 0 0 0</pose>
        <axis>
          <xyz>0 0 1</xyz>
          <limit>
            <lower>-1</lower>
            <upper>1</upper>
            <velocity>1</velocity>
            <effort>500</effort>
          </limit>
          <dynamics>
            <damping>3</damping>
          </dynamics>
        </axis>
    </joint>

    <joint name="base-to-platform" type="fixed">
      <parent>base</parent>
      <child>lower_platform</child>
    </joint>

    <!-- Fix to the world -->
    <joint name="foundation" type="fixed">
      <parent>world</parent>
      <child>root</child>
    </joint>

    <!-- PLUGINS -->
    <plugin
      filename="gz-sim-joint-position-controller-system"
      name="gz::sim::systems::JointPositionController">
      <joint_name>heave</joint_name>
      <use_velocity_commands>true</use_velocity_commands>
      <p_gain>1</p_gain>
      <i_gain>0.1</i_gain>
      <d_gain>0.01</d_gain>
      <i_max>1</i_max>
      <i_min>-1</i_min>
      <topic>heave_ctrl</topic>
      <initial_position>1</initial_position>
    </plugin>

    <plugin
    filename="gz-sim-joint-state-publisher-system"
    name="gz::sim::systems::JointStatePublisher">
      <joint_name>heave</joint_name>
    </plugin>

  </model>
</sdf>
